<mujoco>
	<option timestep="0.0001" integrator="RK4" >
		<flag sensornoise="enable" energy="enable" contact="disable" />
	</option>
	<worldbody>
        <light diffuse=".5 .5 .5" pos="0 0 3" dir="0 0 -1"/>
		<geom type="plane" size="1 1 0.1" rgba=".9 0 0 1"/>
		<body pos="0 0 2.3" euler="0 180 0">
			<joint name="pin" type="hinge" axis = "0 -1 0" limited="true" range="-180 180" pos="0 0 -0.5"/>
			<geom type="cylinder" size="0.05 0.5" rgba="0 .9 0 1" mass="3.5"/>
			<body pos="0 0.1 1" euler="0 0 0">
				<joint name="pin2" type="hinge" axis = "0 -1 0" limited="true" range="0 90" pos="0 0 -0.5"/>
				<geom type="cylinder" size="0.05 0.5" rgba="0 0 .9 1" mass="1.5"/>
				<body pos="0 0 0.55" euler="0 0 0">
					<geom type="sphere" size="0.07" rgba="0.9 0 0 1" mass="0.4"/>
					<!-- <site name="endeff" pos="0 0 0.2" size="0.1"/> -->
				</body>
			</body>
		</body>
	</worldbody>
	<actuator>
		<motor joint="pin" name="torque" gear="1" ctrllimited="true" ctrlrange="-100 100" />
		<position name="pservo1" joint="pin" kp="10" />
		<velocity name="vservo1" joint="pin" kv="10" />
		<motor joint="pin2" name="torque2" gear="1" ctrllimited="true" ctrlrange="-100 100" />
		<position name="pservo2" joint="pin2" kp="10" />
		<velocity name="vservo2" joint="pin2" kv="10" />
	</actuator>

	<!-- <sensor>
		<framepos objtype="site" objname="endeff"/>
		<framelinvel objtype="site" objname="endeff"/>
	</sensor> -->

	<!-- <sensor>
		<jointpos joint="pin" noise="0.2"/>
		<jointvel joint="pin" noise="1" />
	</sensor> -->
</mujoco>
